<?xml version="1.0" ?>
<robot name="my_robo">
  
  <material name="red">
    <color rgba="1.0 0.0 0.0 1.0"/>
  </material>
  <material name="green">
    <color rgba="0.0 1.0 0.0 1.0"/>
  </material>
  <material name="blue">
    <color rgba="0.0 0.0 1.0 1.0"/>
  </material>
  

  
  <joint name="base_footprint_2_base_link_0" type="fixed">
    <parent link="base_footprint"/>
    <child link="base_link_0"/>
    <origin rpy="0 0 0" xyz="0 0 0"/>
    
  </joint>
  


  <!-- base_link -->
  <link name="base_link_0">
    <collision>
      <origin rpy="0 0 0" xyz="0 0 0.0"/>
      <geometry>
        <box size="0.5 0.5 0"/>
      </geometry>
    </collision>
    <visual>
      <origin rpy="0 0 0" xyz="0 0 0.0"/>
      <geometry>
        <box size="0.5 0.5 0"/>
      </geometry>
      <material name="blue"/>
    </visual>
    <inertial>
      <origin rpy="0 0 0" xyz="0 0 0.0"/>
      <mass value="0"/>
      <inertia ixx="0" ixy="0" ixz="0" iyy="0" iyz="0" izz="0"/>
    </inertial>
  </link>

  
  <joint name="base_link_0_2_Link1" type="fixed">
    <parent link="base_link_0"/>
    <child link="Link1"/>
    <origin rpy="0 0 0" xyz="0 0 0"/>
    
  </joint>
  
  <gazebo reference="base_link_0">
    <material>Gazebo/Red</material>
  </gazebo>
  <transmission name="trans0">
    <type>transmission_interface/SimpleTransmission</type>
    <joint name="base_link_0_2_Link1"> 
      <hardwareInterface>EffortJointInterface</hardwareInterface>
    </joint>
    <actuator name="motor0">
       <hardwareInterface>EffortJointInterface</hardwareInterface>
      <mechanicalReduction>1</mechanicalReduction>
    </actuator>
  </transmission>

  <!-- Link1 -->
  <link name="Link1">
    <collision>
      <origin rpy="0 0 0" xyz="0 0 0.05"/>
      <geometry>
        <box size="0.05 0.05 0.1"/>
      </geometry>
    </collision>
    <visual>
      <origin rpy="0 0 0" xyz="0 0 0.05"/>
      <geometry>
        <box size="0.05 0.05 0.1"/>
      </geometry>
      <material name="red"/>
    </visual>
    <inertial>
      <origin rpy="0 0 0" xyz="0 0 0.05"/>
      <mass value="1"/>
      <inertia ixx="1" ixy="0" ixz="0" iyy="1" iyz="0" izz="1"/>
    </inertial>
  </link>

  
  <joint name="Link1_2_Link2" type="revolute">
    <parent link="Link1"/>
    <child link="Link2"/>
    <origin rpy="0 0 0" xyz="0 0 0.1"/>
    
    <axis xyz="0 0 1"/>
    <limit effort="30" lower="-2.616" upper="2.617" velocity="1.571"/>
    
  </joint>
  
  <gazebo reference="Link1">
    <material>Gazebo/Red</material>
  </gazebo>
  <transmission name="trans1">
    <type>transmission_interface/SimpleTransmission</type>
    <joint name="Link1_2_Link2"> 
      <hardwareInterface>EffortJointInterface</hardwareInterface>
    </joint>
    <actuator name="motor1">
       <hardwareInterface>EffortJointInterface</hardwareInterface>
      <mechanicalReduction>1</mechanicalReduction>
    </actuator>
  </transmission>
 


  <!-- Link2 -->
  <link name="Link2">
    <collision>
      <origin rpy="0 0 0" xyz="0 0 0.05"/>
      <geometry>
        <box size="0 0 0"/>
      </geometry>
    </collision>
    <visual>
      <origin rpy="0 0 0" xyz="0 0 0.05"/>
      <geometry>
        <box size="0 0 0"/>
      </geometry>
      <material name="green"/>
    </visual>
    <inertial>
      <origin rpy="0 0 0" xyz="0 0 0.05"/>
      <mass value="1"/>
      <inertia ixx="1" ixy="0" ixz="0" iyy="1" iyz="0" izz="1"/>
    </inertial>
  </link>

  
  <joint name="Link2_2_Link3" type="revolute">
    <parent link="Link2"/>
    <child link="Link3"/>
    <origin rpy="0 0 0" xyz="0 0 0"/>
    
    <axis xyz="0 1 0"/>
    <limit effort="30" lower="-2.616" upper="2.617" velocity="1.571"/>
    
  </joint>
  
  <gazebo reference="Link2">
    <material>Gazebo/Red</material>
  </gazebo>
  <transmission name="trans2">
    <type>transmission_interface/SimpleTransmission</type>
    <joint name="Link2_2_Link3"> 
      <hardwareInterface>EffortJointInterface</hardwareInterface>
    </joint>
    <actuator name="motor2">
       <hardwareInterface>EffortJointInterface</hardwareInterface>
      <mechanicalReduction>1</mechanicalReduction>
    </actuator>
  </transmission>

  
  <joint name="Link2_2_RLink1" type="fixed">
    <parent link="Link2"/>
    <child link="RLink1"/>
    <origin rpy="0 0 0" xyz="0 0.025 0.05"/>
    
  </joint>
  
  <gazebo reference="Link2">
    <material>Gazebo/Red</material>
  </gazebo>
  <transmission name="trans3">
    <type>transmission_interface/SimpleTransmission</type>
    <joint name="Link2_2_RLink1"> 
      <hardwareInterface>EffortJointInterface</hardwareInterface>
    </joint>
    <actuator name="motor3">
       <hardwareInterface>EffortJointInterface</hardwareInterface>
      <mechanicalReduction>1</mechanicalReduction>
    </actuator>
  </transmission>

  
  <joint name="Link2_2_LLink1" type="fixed">
    <parent link="Link2"/>
    <child link="LLink1"/>
    <origin rpy="0 0 0" xyz="0 -0.025 0.05"/>
    
  </joint>
  
  <gazebo reference="Link2">
    <material>Gazebo/Red</material>
  </gazebo>
  <transmission name="trans4">
    <type>transmission_interface/SimpleTransmission</type>
    <joint name="Link2_2_LLink1"> 
      <hardwareInterface>EffortJointInterface</hardwareInterface>
    </joint>
    <actuator name="motor4">
       <hardwareInterface>EffortJointInterface</hardwareInterface>
      <mechanicalReduction>1</mechanicalReduction>
    </actuator>
  </transmission>

  <!-- Link3 -->
  <link name="Link3">
    <collision>
      <origin rpy="0 0 0" xyz="0 0 0.05"/>
      <geometry>
        <box size="0.05 0.05 0.1"/>
      </geometry>
    </collision>
    <visual>
      <origin rpy="0 0 0" xyz="0 0 0.05"/>
      <geometry>
        <box size="0.05 0.05 0.1"/>
      </geometry>
      <material name="blue"/>
    </visual>
    <inertial>
      <origin rpy="0 0 0" xyz="0 0 0.05"/>
      <mass value="1"/>
      <inertia ixx="1" ixy="0" ixz="0" iyy="1" iyz="0" izz="1"/>
    </inertial>
  </link>

  
  <joint name="Link3_2_Link4" type="revolute">
    <parent link="Link3"/>
    <child link="Link4"/>
    <origin rpy="0 0 0" xyz="0 0 0.1"/>
    
    <axis xyz="1 0 0"/>
    <limit effort="30" lower="-2.616" upper="2.617" velocity="1.571"/>
    
  </joint>
  
  <gazebo reference="Link3">
    <material>Gazebo/Red</material>
  </gazebo>
  <transmission name="trans5">
    <type>transmission_interface/SimpleTransmission</type>
    <joint name="Link3_2_Link4"> 
      <hardwareInterface>EffortJointInterface</hardwareInterface>
    </joint>
    <actuator name="motor5">
       <hardwareInterface>EffortJointInterface</hardwareInterface>
      <mechanicalReduction>1</mechanicalReduction>
    </actuator>
  </transmission>

  <!-- Link4 -->
  <link name="Link4">
    <collision>
      <origin rpy="0 0 0" xyz="0 0 0.05"/>
      <geometry>
        <box size="0.05 0.05 0.1"/>
      </geometry>
    </collision>
    <visual>
      <origin rpy="0 0 0" xyz="0 0 0.05"/>
      <geometry>
        <box size="0.05 0.05 0.1"/>
      </geometry>
      <material name="blue"/>
    </visual>
    <inertial>
      <origin rpy="0 0 0" xyz="0 0 0.05"/>
      <mass value="1"/>
      <inertia ixx="1" ixy="0" ixz="0" iyy="1" iyz="0" izz="1"/>
    </inertial>
  </link>

  
  <joint name="Link4_2_Link5" type="revolute">
    <parent link="Link4"/>
    <child link="Link5"/>
    <origin rpy="0 0 0" xyz="0 0 0.1"/>
    
    <axis xyz="1 0 0"/>
    <limit effort="30" lower="-2.616" upper="2.617" velocity="1.571"/>
    
  </joint>
  
  <gazebo reference="Link4">
    <material>Gazebo/Red</material>
  </gazebo>
  <transmission name="trans6">
    <type>transmission_interface/SimpleTransmission</type>
    <joint name="Link4_2_Link5"> 
      <hardwareInterface>EffortJointInterface</hardwareInterface>
    </joint>
    <actuator name="motor6">
       <hardwareInterface>EffortJointInterface</hardwareInterface>
      <mechanicalReduction>1</mechanicalReduction>
    </actuator>
  </transmission>

  <!-- Link5 -->
  <link name="Link5">
    <collision>
      <origin rpy="0 0 0" xyz="0 0 0.05"/>
      <geometry>
        <box size="0.05 0.05 0.1"/>
      </geometry>
    </collision>
    <visual>
      <origin rpy="0 0 0" xyz="0 0 0.05"/>
      <geometry>
        <box size="0.05 0.05 0.1"/>
      </geometry>
      <material name="green"/>
    </visual>
    <inertial>
      <origin rpy="0 0 0" xyz="0 0 0.05"/>
      <mass value="1"/>
      <inertia ixx="1" ixy="0" ixz="0" iyy="1" iyz="0" izz="1"/>
    </inertial>
  </link>

  
  <joint name="Link5_2_Link6" type="fixed">
    <parent link="Link5"/>
    <child link="Link6"/>
    <origin rpy="0 0 0" xyz="0 0 0.1"/>
    
  </joint>
  
  <gazebo reference="Link5">
    <material>Gazebo/Red</material>
  </gazebo>
  <transmission name="trans7">
    <type>transmission_interface/SimpleTransmission</type>
    <joint name="Link5_2_Link6"> 
      <hardwareInterface>EffortJointInterface</hardwareInterface>
    </joint>
    <actuator name="motor7">
       <hardwareInterface>EffortJointInterface</hardwareInterface>
      <mechanicalReduction>1</mechanicalReduction>
    </actuator>
  </transmission>

  <!-- Link6 -->
  <link name="Link6">
    <collision>
      <origin rpy="0 0 0" xyz="0 0 0.05"/>
      <geometry>
        <box size="0.05 0.05 0.1"/>
      </geometry>
    </collision>
    <visual>
      <origin rpy="0 0 0" xyz="0 0 0.05"/>
      <geometry>
        <box size="0.05 0.05 0.1"/>
      </geometry>
      <material name="red"/>
    </visual>
    <inertial>
      <origin rpy="0 0 0" xyz="0 0 0.05"/>
      <mass value="1"/>
      <inertia ixx="1" ixy="0" ixz="0" iyy="1" iyz="0" izz="1"/>
    </inertial>
  </link>

  <gazebo reference="Link6">
    <material>Gazebo/Red</material>
  </gazebo>

  <!-- RLink1 -->
  <link name="RLink1">
    <collision>
      <origin rpy="0 0 0" xyz="0 0.05 0"/>
      <geometry>
        <box size="0.05 0.1 0.05"/>
      </geometry>
    </collision>
    <visual>
      <origin rpy="0 0 0" xyz="0 0.05 0"/>
      <geometry>
        <box size="0.05 0.1 0.05"/>
      </geometry>
      <material name="blue"/>
    </visual>
    <inertial>
      <origin rpy="0 0 0" xyz="0 0.05 0"/>
      <mass value="1"/>
      <inertia ixx="1" ixy="0" ixz="0" iyy="1" iyz="0" izz="1"/>
    </inertial>
  </link>

  
  <joint name="RLink1_2_RLink2" type="revolute">
    <parent link="RLink1"/>
    <child link="RLink2"/>
    <origin rpy="0 0 0" xyz="0 0.1 0"/>
    
    <axis xyz="1 0 0"/>
    <limit effort="30" lower="-2.616" upper="2.617" velocity="1.571"/>
    
  </joint>
  
  <gazebo reference="RLink1">
    <material>Gazebo/Red</material>
  </gazebo>
  <transmission name="trans8">
    <type>transmission_interface/SimpleTransmission</type>
    <joint name="RLink1_2_RLink2"> 
      <hardwareInterface>EffortJointInterface</hardwareInterface>
    </joint>
    <actuator name="motor8">
       <hardwareInterface>EffortJointInterface</hardwareInterface>
      <mechanicalReduction>1</mechanicalReduction>
    </actuator>
  </transmission>

  <!-- RLink2 -->
  <link name="RLink2">
    <collision>
      <origin rpy="0 0 0" xyz="0 0.05 0"/>
      <geometry>
        <box size="0.05 0.1 0.05"/>
      </geometry>
    </collision>
    <visual>
      <origin rpy="0 0 0" xyz="0 0.05 0"/>
      <geometry>
        <box size="0.05 0.1 0.05"/>
      </geometry>
      <material name="green"/>
    </visual>
    <inertial>
      <origin rpy="0 0 0" xyz="0 0.05 0"/>
      <mass value="1"/>
      <inertia ixx="1" ixy="0" ixz="0" iyy="1" iyz="0" izz="1"/>
    </inertial>
  </link>

  
  <joint name="RLink2_2_RLink3" type="fixed">
    <parent link="RLink2"/>
    <child link="RLink3"/>
    <origin rpy="0 0 0" xyz="0 0.1 0"/>
    
  </joint>
  
  <gazebo reference="RLink2">
    <material>Gazebo/Red</material>
  </gazebo>
  <transmission name="trans9">
    <type>transmission_interface/SimpleTransmission</type>
    <joint name="RLink2_2_RLink3"> 
      <hardwareInterface>EffortJointInterface</hardwareInterface>
    </joint>
    <actuator name="motor9">
       <hardwareInterface>EffortJointInterface</hardwareInterface>
      <mechanicalReduction>1</mechanicalReduction>
    </actuator>
  </transmission>

  <!-- RLink3 -->
  <link name="RLink3">
    <collision>
      <origin rpy="0 0 0" xyz="0 0.05 0"/>
      <geometry>
        <box size="0.05 0.1 0.05"/>
      </geometry>
    </collision>
    <visual>
      <origin rpy="0 0 0" xyz="0 0.05 0"/>
      <geometry>
        <box size="0.05 0.1 0.05"/>
      </geometry>
      <material name="red"/>
    </visual>
    <inertial>
      <origin rpy="0 0 0" xyz="0 0.05 0"/>
      <mass value="1"/>
      <inertia ixx="1" ixy="0" ixz="0" iyy="1" iyz="0" izz="1"/>
    </inertial>
  </link>

  <gazebo reference="RLink3">
    <material>Gazebo/Red</material>
  </gazebo>


  <!-- LLink1 -->
  <link name="LLink1">
    <collision>
      <origin rpy="0 0 0" xyz="0 -0.05 0"/>
      <geometry>
        <box size="0.05 0.1 0.05"/>
      </geometry>
    </collision>
    <visual>
      <origin rpy="0 0 0" xyz="0 -0.05 0"/>
      <geometry>
        <box size="0.05 0.1 0.05"/>
      </geometry>
      <material name="blue"/>
    </visual>
    <inertial>
      <origin rpy="0 0 0" xyz="0 -0.05 0"/>
      <mass value="1"/>
      <inertia ixx="1" ixy="0" ixz="0" iyy="1" iyz="0" izz="1"/>
    </inertial>
  </link>

  
  <joint name="LLink1_2_LLink2" type="revolute">
    <parent link="LLink1"/>
    <child link="LLink2"/>
    <origin rpy="0 0 0" xyz="0 -0.1 0"/>
    
    <axis xyz="1 0 0"/>
    <limit effort="30" lower="-2.616" upper="2.617" velocity="1.571"/>
    
  </joint>
  
  <gazebo reference="LLink1">
    <material>Gazebo/Red</material>
  </gazebo>
  <transmission name="trans10">
    <type>transmission_interface/SimpleTransmission</type>
    <joint name="LLink1_2_LLink2"> 
      <hardwareInterface>EffortJointInterface</hardwareInterface>
    </joint>
    <actuator name="motor10">
       <hardwareInterface>EffortJointInterface</hardwareInterface>
      <mechanicalReduction>1</mechanicalReduction>
    </actuator>
  </transmission>

  <!-- LLink2 -->
  <link name="LLink2">
    <collision>
      <origin rpy="0 0 0" xyz="0 -0.05 0"/>
      <geometry>
        <box size="0.05 0.1 0.05"/>
      </geometry>
    </collision>
    <visual>
      <origin rpy="0 0 0" xyz="0 -0.05 0"/>
      <geometry>
        <box size="0.05 0.1 0.05"/>
      </geometry>
      <material name="green"/>
    </visual>
    <inertial>
      <origin rpy="0 0 0" xyz="0 -0.05 0"/>
      <mass value="1"/>
      <inertia ixx="1" ixy="0" ixz="0" iyy="1" iyz="0" izz="1"/>
    </inertial>
  </link>

  
  <joint name="LLink2_2_LLink3" type="fixed">
    <parent link="LLink2"/>
    <child link="LLink3"/>
    <origin rpy="0 0 0" xyz="0 -0.1 0"/>
    
  </joint>
  
  <gazebo reference="LLink2">
    <material>Gazebo/Red</material>
  </gazebo>
  <transmission name="trans11">
    <type>transmission_interface/SimpleTransmission</type>
    <joint name="LLink2_2_LLink3"> 
      <hardwareInterface>EffortJointInterface</hardwareInterface>
    </joint>
    <actuator name="motor11">
       <hardwareInterface>EffortJointInterface</hardwareInterface>
      <mechanicalReduction>1</mechanicalReduction>
    </actuator>
  </transmission>

  <!-- LLink3 -->
  <link name="LLink3">
    <collision>
      <origin rpy="0 0 0" xyz="0 -0.05 0"/>
      <geometry>
        <box size="0.05 0.1 0.05"/>
      </geometry>
    </collision>
    <visual>
      <origin rpy="0 0 0" xyz="0 -0.05 0"/>
      <geometry>
        <box size="0.05 0.1 0.05"/>
      </geometry>
      <material name="red"/>
    </visual>
    <inertial>
      <origin rpy="0 0 0" xyz="0 -0.05 0"/>
      <mass value="1"/>
      <inertia ixx="1" ixy="0" ixz="0" iyy="1" iyz="0" izz="1"/>
    </inertial>
  </link>

  <gazebo reference="LLink7">
    <material>Gazebo/Red</material>
  </gazebo>
    <gazebo>
    <plugin name="gazebo_ros_control" filename="libgazebo_ros_control.so">
      <robotNamespace>/my_robo</robotNamespace>
    </plugin>
  </gazebo>

</robot>
